Workbook

Sheet Main Data
A1: Forest | B1: Plot Number | C1: Existing | D1: New | E1: Tree Count | F1: Blanking Stocking | G1: Total Stocking | H1: Rework | I1: Comments
A2: Eastern Block | B2: 1 | C2: 5 | D2: 34 | E2: 39 | F2: =Table1[[#This Row],[New]]/0.04 -> 850 | G2: =E2/0.04 -> 975 | H2: No | I2: Reworked this mornings work for open holes. 5 existing trees 34 new
A3: Eastern Block | B3: 2 | C3: 28 | D3: 8 | E3: 36 | F3: =Table1[[#This Row],[New]]/0.04 -> 200 | G3: =E3/0.04 -> 900 | H3: No | I3: 28 existing trees 8 new
A4: Eastern Block | B4: 3 | D4: 37 | E4: 37 | F4: =Table1[[#This Row],[New]]/0.04 -> 925 | G4: =E4/0.04 -> 925 | H4: No | I4: 11.85_x000D_ 37 trees_x000D_ A few trees in area are in a poor location (in long grass mounds, needed to be moved or screefed better
A5: Eastern Block | B5: 4 | C5: 31 | D5: 7 | E5: 38 | F5: =Table1[[#This Row],[New]]/0.04 -> 175 | G5: =E5/0.04 -> 950 | H5: No | I5: 31 existing trees. 7 new. Moved due to scrub
A6: Eastern Block | B6: 5 | D6: 35 | E6: 35 | F6: =Table1[[#This Row],[New]]/0.04 -> 875 | G6: =E6/0.04 -> 875 | H6: No | I6: 11.34_x000D_ 35 trees
A7: Eastern Block | B7: 6 | E7: 49 | F7: =Table1[[#This Row],[New]]/0.04 -> 0 | G7: =E7/0.04 -> 1225 | H7: Yes | I7: No rework. Immediate feedback. Deductions and reworks to follow if no improvement.
A8: Eastern Block | B8: 7 | E8: 42 | F8: =Table1[[#This Row],[New]]/0.04 -> 0 | G8: =E8/0.04 -> 1050 | H8: No | I8: Sph better. Contractor shown where sph is high. If not improvement deductions
A9: Eastern Block | B9: 8 | E9: 41 | F9: =Table1[[#This Row],[New]]/0.04 -> 0 | G9: =E9/0.04 -> 1025 | H9: No | I9: Plot moved off track. A little high again. Better. Quality is good. The sph is high due to the original planting. Some close planting around track. The actual blanking is good spacing.
A10: Eastern Block | B10: 9 | C10: 11 | D10: 35 | E10: 46 | F10: =Table1[[#This Row],[New]]/0.04 -> 875 | G10: =E10/0.04 -> 1150 | H10: No | I10: 24 deg_x000D_ 35 new_x000D_ 11 existing
A11: Eastern Block | B11: 10 | C11: 9 | D11: 27 | E11: 36 | F11: =Table1[[#This Row],[New]]/0.04 -> 675 | G11: =E11/0.04 -> 900 | H11: No | I11: 15 deg_x000D_ 27 new_x000D_ 9 existing
A12: Eastern Block | B12: 11 | C12: 38 | D12: 10 | E12: 48 | F12: =Table1[[#This Row],[New]]/0.04 -> 250 | G12: =E12/0.04 -> 1200 | H12: No | I12: 26deg_x000D_ 10 new_x000D_ 38 existing.
A13: Eastern Block | B13: 12 | C13: 7 | D13: 30 | E13: 37 | F13: =Table1[[#This Row],[New]]/0.04 -> 750 | G13: =E13/0.04 -> 925 | H13: No | I13: 22 deg_x000D_ 30 new _x000D_ 7 old
A14: Eastern Block | B14: 13 | C14: 8 | D14: 32 | E14: 40 | F14: =Table1[[#This Row],[New]]/0.04 -> 800 | G14: =E14/0.04 -> 1000 | H14: No | I14: 10 deg_x000D_ 32 new_x000D_ 8 existing_x000D_ _x000D_ 2 not vertical
A15: Eastern Block | B15: 14 | C15: 14 | D15: 23 | E15: 37 | F15: =Table1[[#This Row],[New]]/0.04 -> 575 | G15: =E15/0.04 -> 925 | H15: No | I15: 11.85_x000D_ 23 new_x000D_ 14 existing
A16: Eastern Block | B16: 15 | C16: 0 | D16: 30 | E16: 30 | F16: =Table1[[#This Row],[New]]/0.04 -> 750 | G16: =E16/0.04 -> 750 | H16: No | I16: 12deg_x000D_ 30 new _x000D_ Odd spacing. Hard to follow rows
A17: Eastern Block | B17: 16 | C17: 0 | D17: 40 | E17: 40 | F17: =Table1[[#This Row],[New]]/0.04 -> 1000 | G17: =E17/0.04 -> 1000 | H17: No | I17: 0deg _x000D_ 40new
A18: Eastern Block | B18: 17 | C18: 2 | D18: 28 | E18: 30 | F18: =Table1[[#This Row],[New]]/0.04 -> 700 | G18: =E18/0.04 -> 750 | H18: No | I18: 18 deg_x000D_ 28 new_x000D_ 2 old _x000D_ _x000D_ 1 placement issue. _x000D_ _x000D_ Wide spacing in areas
A19: Front Farm | B19: 1 | C19: 36 | D19: 5 | E19: 41 | F19: =Table1[[#This Row],[New]]/0.04 -> 125 | G19: =E19/0.04 -> 1025 | H19: No | I19: 28 deg_x000D_ 5 new_x000D_ 36 existing_x000D_
A20: Front Farm | B20: 2 | C20: 19 | D20: 19 | E20: 38 | F20: =Table1[[#This Row],[New]]/0.04 -> 475 | G20: =E20/0.04 -> 950 | H20: No | I20: 11.6_x000D_ 19 new_x000D_ 19 old
A21: Front Farm | B21: 3 | C21: 18 | D21: 21 | E21: 39 | F21: =Table1[[#This Row],[New]]/0.04 -> 525 | G21: =E21/0.04 -> 975 | H21: No | I21: 26 deg_x000D_ 21 new _x000D_ 18 old_x000D_ _x000D_ 1 dropped
... A33: Front Farm | B33: 15 | C33: 15 | D33: 25 | E33: 40 | F33: =Table1[[#This Row],[New]]/0.04 -> 625 | G33: =E33/0.04 -> 1000 | H33: No | I33: Nt 25 et 15 total 40
A34: Front Farm | B34: 16 | C34: 11 | D34: 26 | E34: 37 | F34: =Table1[[#This Row],[New]]/0.04 -> 650 | G34: =E34/0.04 -> 925 | H34: No | I34: 11.41
A35: Front Farm | B35: 17 | C35: 24 | D35: 17 | E35: 40 | F35: =Table1[[#This Row],[New]]/0.04 -> 425 | G35: =E35/0.04 -> 1000 | H35: No | I35: P4 24 et 16 nt 40 total
A36: Front Farm | B36: 18 | C36: 8 | D36: 33 | E36: 41 | F36: =Table1[[#This Row],[New]]/0.04 -> 825 | G36: =E36/0.04 -> 1025 | H36: No | I36: P5 41 Total 33 New 8existing
A37: Front Farm | B37: 19 | C37: 32 | D37: 6 | E37: 38 | F37: =Table1[[#This Row],[New]]/0.04 -> 150 | G37: =E37/0.04 -> 950 | H37: No | I37: P6 32 existing 6 new 38 total
A38: Front Farm | B38: 20 | C38: 2 | D38: 36 | E38: 38 | F38: =Table1[[#This Row],[New]]/0.04 -> 900 | G38: =E38/0.04 -> 950 | H38: No | I38: 11.29_x000D_ 38 trees_x000D_ 2 orginial trees_x000D_ Few trees with a heel indent at base of tree, corrected crew on this and had holes remedied
A39: Front Farm | B39: 21 | C39: 2 | D39: 41 | E39: 43 | F39: =Table1[[#This Row],[New]]/0.04 -> 1025 | G39: =E39/0.04 -> 1075 | H39: No | I39: 11.41_x000D_ 41 trees_x000D_ 2 orginial trees
A40: Front Farm | B40: 22 | D40: 40 | E40: 40 | F40: =Table1[[#This Row],[New]]/0.04 -> 1000 | G40: =E40/0.04 -> 1000 | H40: No | I40: 11.76_x000D_ 40 trees_x000D_ 1 open hole
A41: Front Farm | B41: 23 | C41: 2 | D41: 35 | E41: 37 | F41: =Table1[[#This Row],[New]]/0.04 -> 875 | G41: =E41/0.04 -> 925 | H41: No | I41: 11.33_x000D_ 37 trees_x000D_ 2 orginial
A42: Front Farm | B42: 24 | F42: =Table1[[#This Row],[New]]/0.04 -> 0 | G42: =E42/0.04 -> 0 | H42: Yes | I42: Shallow planting, pods exposed
A43: Soldiers Road | B43: 1 | C43: 25 | D43: 23 | E43: 48 | F43: =Table1[[#This Row],[New]]/0.04 -> 575 | G43: =E43/0.04 -> 1200 | H43: No | I43: 23 are blanked trees, crew have followed orginial rows, need to skip odd 1 as they are too close causing high stocking, have told crew to skip rows if they are too close
A44: Soldiers Road | B44: 2 | C44: =Table1[[#This Row],[Tree Count]]-Table1[[#This Row],[New]] -> 3 | D44: 35 | E44: 38 | F44: =Table1[[#This Row],[New]]/0.04 -> 875 | G44: =E44/0.04 -> 950 | H44: No | I44: 35 blanked
A45: Soldiers Road | B45: 3 | C45: =Table1[[#This Row],[Tree Count]]-Table1[[#This Row],[New]] -> 4 | D45: 34 | E45: 38 | F45: =Table1[[#This Row],[New]]/0.04 -> 850 | G45: =E45/0.04 -> 950 | H45: No | I45: 34 blanked
A46: Soldiers Road | B46: 4 | C46: =Table1[[#This Row],[Tree Count]]-Table1[[#This Row],[New]] -> 23 | D46: 20 | E46: 43 | F46: =Table1[[#This Row],[New]]/0.04 -> 500 | G46: =E46/0.04 -> 1075 | H46: No | I46: 20 blanked, area appears to have been blanked already with old trees scattered amongst older trees
A47: Soldiers Road | B47: 5 | C47: =Table1[[#This Row],[Tree Count]]-Table1[[#This Row],[New]] -> 26 | D47: 13 | E47: 39 | F47: =Table1[[#This Row],[New]]/0.04 -> 325 | G47: =E47/0.04 -> 975 | H47: No | I47: 13 blanked, area has already been blanked in the past, some old trees planted next to older trees
A48: Soldiers Road | B48: 6 | C48: =Table1[[#This Row],[Tree Count]]-Table1[[#This Row],[New]] -> 2 | D48: 28 | E48: 30 | F48: =Table1[[#This Row],[New]]/0.04 -> 700 | G48: =E48/0.04 -> 750 | H48: No | I48: 28 blanked
A49: Soldiers Road | B49: 7 | C49: =Table1[[#This Row],[Tree Count]]-Table1[[#This Row],[New]] -> 0 | D49: 37 | E49: 37 | F49: =Table1[[#This Row],[New]]/0.04 -> 925 | G49: =E49/0.04 -> 925 | H49: No | I49: 37 blanked
A50: Soldiers Road | B50: 8 | C50: 30 | D50: 13 | E50: 43 | F50: =Table1[[#This Row],[New]]/0.04 -> 325 | G50: =E50/0.04 -> 1075 | H50: No | I50: 43 total 13 new 30existing
A51: Soldiers Road | B51: 9 | C51: 23 | D51: 15 | E51: 38 | F51: =Table1[[#This Row],[New]]/0.04 -> 375 | G51: =E51/0.04 -> 950 | H51: No | I51: 38 total 23existing 15 new
...

Sheet Sheet3
A1: OBJECTID * | D1: tYPE | E1: GlobalID * | F1: PlotNum | H1: New | I1: Existing | J1: TreeCount | K1: SPH | L1: BlankedSPH | M1: Shape * | T1: Forest | U1: PlotNum | V1: Existing | W1: New | X1: TreeCount | AA1: Rework | AB1: Comments
A2: 82 | D2: 1 | E2: {80705EE2-20BD-48CA-AE4C-30601966106B} | F2: 1 | H2: 13 | I2: 37 | J2: 50 | K2: 1250 | L2: 325 | M2: Point Z | T2: Back Farm | U2: 1 | V2: 37 | W2: 13 | X2: 50 | AA2: {=_xlfn.IFS(D2=1,"No",D2=2,"Yes")} -> No | AB2: Steep face; original lines slightly too close, and blanking has followed gaps/lines.
A3: 83 | D3: 1 | E3: {D96CF263-2DA8-4A39-9106-28CC32517AAE} | F3: 2 | H3: 0 | I3: 43 | J3: 43 | K3: 1075 | L3: 0 | M3: Point Z | T3: Back Farm | U3: 2 | V3: 43 | W3: 0 | X3: 43 | AA3: {=_xlfn.IFS(D3=1,"No",D3=2,"Yes")} -> No | AB3: Minimal blanking required in this area.
A4: 84 | D4: 1 | E4: {7EA99D41-201C-45FC-8584-F1302AB58031} | F4: 3 | H4: 5 | I4: 38 | J4: 43 | K4: 1075 | L4: 125 | M4: Point Z | T4: Back Farm | U4: 3 | V4: 38 | W4: 5 | X4: 43 | AA4: {=_xlfn.IFS(D4=1,"No",D4=2,"Yes")} -> No | AB4: Good growth rate and survival in previous planting.
A5: 85 | D5: 1 | E5: {23416B60-B43C-481B-8137-7D823C46FDE2} | F5: 4 | H5: 15 | I5: 25 | J5: 40 | K5: 1000 | L5: 375 | M5: Point Z | T5: Back Farm | U5: 4 | V5: 25 | W5: 15 | X5: 40 | AA5: {=_xlfn.IFS(D5=1,"No",D5=2,"Yes")} -> No | AB5: Quality.
A6: 215 | D6: 1 | E6: {08EE35B4-ACEF-4839-B0B9-DD7E1D8C2B82} | F6: 5 | H6: 30 | I6: 13 | J6: 43 | K6: <Null> | L6: <Null> | M6: Point Z | T6: Back Farm | U6: 5 | V6: 13 | W6: 30 | X6: 43 | AA6: {=_xlfn.IFS(D6=1,"No",D6=2,"Yes")} -> No | AB6: 30 blanked
A7: 216 | D7: 1 | E7: {BFE989FF-54ED-4604-8851-7124922E15F1} | F7: 6 | H7: 33 | I7: 2 | J7: 35 | K7: <Null> | L7: <Null> | M7: Point Z | T7: Back Farm | U7: 6 | V7: 2 | W7: 33 | X7: 35 | AA7: {=_xlfn.IFS(D7=1,"No",D7=2,"Yes")} -> No | AB7: 33 blanked
A8: 217 | D8: 1 | E8: {9A018B2D-5E75-4B25-A6B0-35BBC7520E3C} | F8: 7 | H8: 13 | I8: 20 | J8: 33 | K8: <Null> | L8: <Null> | M8: Point Z | T8: Back Farm | U8: 7 | V8: 20 | W8: 13 | X8: 33 | AA8: {=_xlfn.IFS(D8=1,"No",D8=2,"Yes")} -> No | AB8: 13 blanked
A9: 219 | D9: 1 | E9: {A4F2FFAB-CEAB-42E0-8040-9E139F1FC166} | F9: 8 | H9: 23 | I9: 9 | J9: 32 | K9: <Null> | L9: <Null> | M9: Point Z | T9: Back Farm | U9: 8 | V9: 9 | W9: 23 | X9: 32 | AA9: {=_xlfn.IFS(D9=1,"No",D9=2,"Yes")} -> No | AB9: 23 blanked
A10: 220 | D10: 1 | E10: {DAAFFEE5-A95B-47D9-A811-12FB1B0E26C4} | F10: 9 | H10: 25 | I10: 11 | J10: 36 | K10: <Null> | L10: <Null> | M10: Point Z | T10: Back Farm | U10: 9 | V10: 11 | W10: 25 | X10: 36 | AA10: {=_xlfn.IFS(D10=1,"No",D10=2,"Yes")} -> No | AB10: 25 blanked, was 26 but had 2 pulled for being too close to orginial trees
A11: 211 | D11: 1 | E11: {9AF31DAD-DE7C-4E7C-BB77-28EF5A2928E1} | F11: 10 | H11: 17 | I11: 27 | J11: 44 | K11: <Null> | L11: <Null> | M11: Point Z | T11: Back Farm | U11: 10 | V11: 27 | W11: 17 | X11: 44 | AA11: {=_xlfn.IFS(D11=1,"No",D11=2,"Yes")} -> No | AB11: 17 trees blanked. 27 trees established within plot. Pods are planted well.
A12: 212 | D12: 1 | E12: {7D4B77BC-65A8-4B79-802E-A24AA375D9FE} | F12: 11 | H12: <Null> | I12: <Null> | J12: 46 | K12: <Null> | L12: <Null> | M12: Point Z | T12: Back Farm | U12: 11 | V12: <Null> | W12: <Null> | X12: 46 | AA12: {=_xlfn.IFS(D12=1,"No",D12=2,"Yes")} -> No | AB12: Rework was completed for over stocking. Contour lines caught extra trees in middle rows.
A13: 213 | D13: 1 | E13: {1832EF97-F8AB-4EC2-B301-0E60AE1B56C6} | F13: 12 | H13: 23 | I13: 25 | J13: 48 | K13: <Null> | L13: <Null> | M13: Point Z | T13: Back Farm | U13: 12 | V13: 25 | W13: 23 | X13: 48 | AA13: {=_xlfn.IFS(D13=1,"No",D13=2,"Yes")} -> No | AB13: Loose tree fixed and isolated. 23 blanked 25 established. Initial spacing looks close
A14: 214 | D14: 1 | E14: {3A10B77E-189D-45DF-AC33-EBBE2E9B53B3} | F14: 13 | H14: <Null> | I14: <Null> | J14: 47 | K14: <Null> | L14: <Null> | M14: Point Z | T14: Back Farm | U14: 13 | V14: <Null> | W14: <Null> | X14: 47 | AA14: {=_xlfn.IFS(D14=1,"No",D14=2,"Yes")} -> No | AB14: Good planting. A lot of pig rooting in the area.
A15: 218 | D15: 2 | E15: {390EA86C-55C4-4E83-BFB7-B24B7F280992} | F15: 14 | H15: 23 | I15: 9 | J15: 32 | K15: <Null> | L15: <Null> | M15: Point Z | T15: Back Farm | U15: 14 | V15: 9 | W15: 23 | X15: 32 | AA15: {=_xlfn.IFS(D15=1,"No",D15=2,"Yes")} -> Yes | AB15: 23 blanked, had a planter in area come and fill some wide spacing in area
A16: 221 | D16: 1 | E16: {1E395F7D-C083-4BE5-90F6-81BC38C8DF06} | F16: 15 | H16: 28 | I16: 15 | J16: 43 | K16: <Null> | L16: <Null> | M16: Point Z | T16: Back Farm | U16: 15 | V16: 15 | W16: 28 | X16: 43 | AA16: {=_xlfn.IFS(D16=1,"No",D16=2,"Yes")} -> No | AB16: 28 blanked, a couple rows where between trees are pushing a bit close, right behind planters will correct otherwise rework if continues
A17: 222 | D17: 1 | E17: {B663BB36-12A6-4EBE-B933-2B6B81AE9683} | F17: 16 | H17: 30 | I17: 4 | J17: 34 | K17: <Null> | L17: <Null> | M17: Point Z | T17: Back Farm | U17: 16 | V17: 4 | W17: 30 | X17: 34 | AA17: {=_xlfn.IFS(D17=1,"No",D17=2,"Yes")} -> No | AB17: Lost plot data, from memory blanked trees was early 30s with 4 orginial trees
A18: 95 | D18: 1 | E18: {299D6594-DFD9-48C6-94D6-6B2F45F99380} | F18: 17 | H18: 21 | I18: 21 | J18: 42 | K18: 1050 | L18: 525 | M18: Point Z | T18: Back Farm | U18: 17 | V18: 21 | W18: 21 | X18: 42 | AA18: {=_xlfn.IFS(D18=1,"No",D18=2,"Yes")} -> No | AB18: Plot moved down from the old slip area. Planted above the plot in slips. Existing trees are in poor health. Goats spotted at the top of the face.
A19: 223 | D19: 1 | E19: {D696981C-3B74-4782-AF04-E3248056BE52} | F19: 18 | H19: 35 | I19: 5 | J19: 40 | K19: <Null> | L19: <Null> | M19: Point Z | T19: Back Farm | U19: 18 | V19: 5 | W19: 35 | X19: 40 | AA19: {=_xlfn.IFS(D19=1,"No",D19=2,"Yes")} -> No | AB19: 35 blanked trees
A20: 224 | D20: 1 | E20: {155437BA-6037-48E3-BE80-DE628C44D0D2} | F20: 19 | H20: <Null> | I20: <Null> | J20: 33 | K20: <Null> | L20: <Null> | M20: Point Z | T20: Back Farm | U20: 19 | V20: <Null> | W20: <Null> | X20: 33 | AA20: {=_xlfn.IFS(D20=1,"No",D20=2,"Yes")} -> No | AB20: High amount of exisiting trees.
A21: 225 | D21: 1 | E21: {73C50251-1779-4713-8AD3-EC92CEF34CCD} | F21: 20 | H21: 31 | I21: 10 | J21: 41 | K21: <Null> | L21: <Null> | M21: Point Z | T21: Back Farm | U21: 20 | V21: 10 | W21: 31 | X21: 41 | AA21: {=_xlfn.IFS(D21=1,"No",D21=2,"Yes")} -> No | AB21: 10 exisiting trees, remaining blanked. Plot shifted due to bluff in middle of marked plot location.
A22: 208 | D22: 2 | E22: {CF818A91-84C6-49CC-97FE-EFDF8E8CB900} | F22: 21 | H22: 39 | I22: 6 | J22: 45 | K22: <Null> | L22: <Null> | M22: Point Z | T22: Back Farm | U22: 21 | V22: 6 | W22: 39 | X22: 45 | AA22: {=_xlfn.IFS(D22=1,"No",D22=2,"Yes")} -> Yes | AB22: To pull out some close trees through area, 6 orginial trees in area
A23: 209 | D23: 1 | E23: {3064229E-B370-40CB-937D-9A9E1AF107AC} | F23: 22 | H23: 19 | I23: 18 | J23: 37 | K23: <Null> | L23: <Null> | M23: Point Z | T23: Back Farm | U23: 22 | V23: 18 | W23: 19 | X23: 37 | AA23: {=_xlfn.IFS(D23=1,"No",D23=2,"Yes")} -> No | AB23: 19 blanked, moved plot slightly so fit in an area where plot was not obstructed by tree or creek
A24: 210 | D24: 1 | E24: {A2F68F24-FB5C-4108-9E2A-3F2F6BDDDA18} | F24: 23 | H24: 18 | I24: 17 | J24: 35 | K24: <Null> | L24: <Null> | M24: Point Z | T24: Back Farm | U24: 23 | V24: 17 | W24: 18 | X24: 35 | AA24: {=_xlfn.IFS(D24=1,"No",D24=2,"Yes")} -> No | AB24: 18 blanked, plot is not quite finished, another 4-7 trees still to go in, moved plot out of a gut
A25: 228 | D25: 1 | E25: {4D18200C-4E12-4AE7-BC3F-8775BA31EC06} | F25: 24 | H25: 18 | I25: 26 | J25: 44 | K25: <Null> | L25: <Null> | M25: Point Z | T25: Back Farm | U25: 24 | V25: 26 | W25: 18 | X25: 44 | AA25: {=_xlfn.IFS(D25=1,"No",D25=2,"Yes")} -> No | AB25: 19 deg, 11.6m 44 trees Quality good. 2 non vertical trees 26 existing t 1 tree planted between blanking and an existing tree. Otherwise tree locations good.
A26: 226 | D26: 1 | E26: {06E9FAA8-A0AA-49C7-BBF8-3427823676CA} | F26: 25 | H26: 30 | I26: 9 | J26: 39 | K26: <Null> | L26: <Null> | M26: Point Z | T26: Back Farm | U26: 25 | V26: 9 | W26: 30 | X26: 39 | AA26: {=_xlfn.IFS(D26=1,"No",D26=2,"Yes")} -> No | AB26: 12.01m 39 trees 9 existing. Good planting quality. Grass needs spraying asap. No Issues
A27: 227 | D27: 1 | E27: {F86DCED2-235E-421D-9CAB-AD945828025C} | F27: 26 | H27: 13 | I27: 41 | J27: 54 | K27: <Null> | L27: <Null> | M27: Point Z | T27: Back Farm | U27: 26 | V27: 41 | W27: 13 | X27: 54 | AA27: {=_xlfn.IFS(D27=1,"No",D27=2,"Yes")} -> No | AB27: 16 deg, 11.51m. 54 trees quality good. Reason for high stocking is alot of existing crop is overstocked with close trees but there are gaps where planters have filled. 41 existing. Hard to blank due to existing tree clusters
A28: 88 | D28: 1 | E28: {264350E6-4814-4AF7-8233-928211606F80} | F28: 27 | H28: 8 | I28: 37 | J28: 45 | K28: 1125 | L28: 200 | M28: Point Z | T28: Back Farm | U28: 27 | V28: 37 | W28: 8 | X28: 45 | AA28: {=_xlfn.IFS(D28=1,"No",D28=2,"Yes")} -> No | AB28: Plot moved away from the steep slip area, which was planted. Very steep area, and the original planting lines were close.
A29: 89 | D29: 1 | E29: {48246630-2A56-48BD-95C2-0E2BCED186A9} | F29: 28 | H29: 10 | I29: 26 | J29: 36 | K29: 900 | L29: 250 | M29: Point Z | T29: Back Farm | U29: 28 | V29: 26 | W29: 10 | X29: 36 | AA29: {=_xlfn.IFS(D29=1,"No",D29=2,"Yes")} -> No | AB29: Track buffer on the lower side of the plot. Could have fitted 2–3 trees while maintaining the track buffer. Lots of blanking around the track area.
A30: 230 | D30: 1 | E30: {B5D6A1A6-AD91-41AE-8F51-5D0425F31630} | F30: 29 | H30: 3 | I30: 22 | J30: 25 | K30: <Null> | L30: <Null> | M30: Point Z | T30: Back Farm | U30: 29 | V30: 22 | W30: 3 | X30: 25 | AA30: {=_xlfn.IFS(D30=1,"No",D30=2,"Yes")} -> No | AB30: 11.28m 22 existing 3 blanked Much of plot lost to bog. Large trees. Blanked trees scattered through gaps. In wider area alot of variation. Sometimes areas are well stocked with existing trees. Often gaps.
A31: 90 | D31: 1 | E31: {7DDAD743-2802-482A-8C1E-70076C548EC7} | F31: 30 | H31: 7 | I31: 33 | J31: 40 | K31: 1000 | L31: 175 | M31: Point Z | T31: Back Farm | U31: 30 | V31: 33 | W31: 7 | X31: 40 | AA31: {=_xlfn.IFS(D31=1,"No",D31=2,"Yes")} -> No | AB31: Shifted down from the fence line. Good blanking observed between Plots 31 and 30, up the ridge and fence line.
A32: 91 | D32: 1 | E32: {4E3DD734-B45A-405F-97D3-0C712A15EA56} | F32: 31 | H32: 0 | I32: 38 | J32: 38 | K32: 950 | L32: 0 | M32: Point Z | T32: Back Farm | U32: 31 | V32: 38 | W32: 0 | X32: 38 | AA32: {=_xlfn.IFS(D32=1,"No",D32=2,"Yes")} -> No | AB32: Two historic slips on the lower edge of the plot; unsafe and unplantable.
A33: 232 | D33: 1 | E33: {390682B3-CDAD-447C-9837-0EC2713C2341} | F33: 32 | H33: 9 | I33: 33 | J33: 42 | K33: <Null> | L33: <Null> | M33: Point Z | T33: Back Farm | U33: 32 | V33: 33 | W33: 9 | X33: 42 | AA33: {=_xlfn.IFS(D33=1,"No",D33=2,"Yes")} -> No | AB33: 21 deg, 11.68m 42 trees 33 existing Quite a number of damage trees/dying trees. Pest damage bad here Good quality. Roots very good.
A34: 233 | D34: 2 | E34: {CE019050-26E3-4F2B-89D3-2004C70F47EB} | F34: 33 | H34: 14 | I34: 24 | J34: 38 | K34: <Null> | L34: <Null> | M34: Point Z | T34: Back Farm | U34: 33 | V34: 24 | W34: 14 | X34: 38 | AA34: {=_xlfn.IFS(D34=1,"No",D34=2,"Yes")} -> Yes | AB34: 12.28m 38 trees, 1 marginal, maybe 39. 24 existing trees. Roots up. Rework.
A35: 234 | D35: 2 | E35: {70B044EF-1A0F-4B65-9A69-7E51FB334B0E} | F35: 34 | H35: 17 | I35: 20 | J35: 37 | K35: <Null> | L35: <Null> | M35: Point Z | T35: Back Farm | U35: 34 | V35: 20 | W35: 17 | X35: 37 | AA35: {=_xlfn.IFS(D35=1,"No",D35=2,"Yes")} -> Yes | AB35: 11.95m 37 trees Couple close planted trees. Hard to see lines. Perhaps an error. 20 existing. These areas are surprising. Looks like good coverage of trees but its patchy. Roots are pretty marginal..... rework.
A36: 235 | D36: 2 | E36: {F4CE4406-C761-46BB-95BF-6427687D86C2} | F36: 35 | H36: <Null> | I36: <Null> | J36: <Null> | K36: <Null> | L36: <Null> | M36: Point Z | T36: Back Farm | U36: 35 | V36: <Null> | W36: <Null> | X36: <Null> | AA36: {=_xlfn.IFS(D36=1,"No",D36=2,"Yes")} -> Yes | AB36: 11.64m Plenty of trees blanked here. Ran out of paint and lost count. Spacing is fine. Open holes- rework
A37: 92 | D37: 1 | E37: {DB25A1B9-05D2-45C5-9041-169CDBAB028C} | F37: 36 | H37: 9 | I37: 32 | J37: 41 | K37: 1025 | L37: 225 | M37: Point Z | T37: Back Farm | U37: 36 | V37: 32 | W37: 9 | X37: 41 | AA37: {=_xlfn.IFS(D37=1,"No",D37=2,"Yes")} -> No | AB37: One new seedling planted on a heavy lean. Existing crop looking okay, with browsing damage around the base of all trees and bark stripped.
A38: 93 | D38: 1 | E38: {B0182065-C3D5-4616-85A1-5C48264BC44C} | F38: 37 | H38: 42 | I38: 1 | J38: 43 | K38: 1075 | L38: 1050 | M38: Point Z | T38: Back Farm | U38: 37 | V38: 1 | W38: 42 | X38: 43 | AA38: {=_xlfn.IFS(D38=1,"No",D38=2,"Yes")} -> No | AB38: Bluff at the top side of the plot did not affect the planted area. Existing trees are much more prevalent below this plot, away from the bluff/slip material.
A39: 94 | D39: 1 | E39: {A49BC45C-D3FD-4C59-978D-4BBFF391AFF4} | F39: 38 | H39: 10 | I39: 28 | J39: 38 | K39: 950 | L39: 250 | M39: Point Z | T39: Back Farm | U39: 38 | V39: 28 | W39: 10 | X39: 38 | AA39: {=_xlfn.IFS(D39=1,"No",D39=2,"Yes")} -> No | AB39: Plot is just off the track. Lots of browsing damage in older trees; new trees are looking really good. Longer grass here than in the rest of the catchment.
A40: 97 | D40: 1 | E40: {B27D8B3D-910F-47D5-B306-6FC2C177A894} | F40: 39 | H40: 40 | I40: 2 | J40: 42 | K40: 1050 | L40: 1000 | M40: Point Z | T40: Back Farm | U40: 39 | V40: 2 | W40: 40 | X40: 42 | AA40: {=_xlfn.IFS(D40=1,"No",D40=2,"Yes")} -> No | AB40: Good planting; lots of browsing sign on the way to the plot.
...
